#VRML_SIM R2022b utf8
# license: Apache License 2.0
# license url: http://www.apache.org/licenses/LICENSE-2.0
# This is a proto file for Webots for the Robocon2022R1Simplified
# Extracted from: ../protos/robocon2022_r1_meshes/urdf/robocon2022_r1_simplified.urdf

PROTO Robocon2022R1Robot123 [
  field  SFVec3f     translation     0 0 0
  field  SFRotation  rotation        0 0 1 0
  field  SFString    name            "r1"  # Is `Robot.name`.
  field  SFString    controller      "ros"           # Is `Robot.controller`.
  field  MFString    controllerArgs  [
    # "--robot-description=r1/"
    "--auto-publish"
    "--name=r1"
    "--use-ros-control"
  ]          
  field  SFString    customData      ""               # Is `Robot.customData`.
  field  SFBool      supervisor      FALSE            # Is `Robot.supervisor`.
  field  SFBool      synchronization TRUE             # Is `Robot.synchronization`.
  field  SFBool      selfCollision   FALSE            # Is `Robot.selfCollision`.
]
{
  Robot {
    translation IS translation
    rotation IS rotation
    controller IS controller
    controllerArgs IS controllerArgs
    customData IS customData
    supervisor IS supervisor
    synchronization IS synchronization
    selfCollision IS selfCollision
    children [
      Shape {
        appearance DEF base_link_material PBRAppearance {
          roughness 1.000000
          metalness 0
        }
        geometry DEF base_link Mesh {
          url "../protos/robocon2022_r1_meshes/base_link.STL"
        }
      }
      DEF chassis_body Solid {
        children [
          Shape {
            appearance DEF chassis_body_material PBRAppearance {
              baseColor 0.200000 0.200000 0.200000
              roughness 1.000000
              metalness 0
            }
            geometry DEF chassis_body Mesh {
              url "../protos/robocon2022_r1_meshes/chassis_body.STL"
            }
          }
        ]
        name "chassis_body"
        boundingObject Transform {
          translation 0 0 0.12
          children [
            Box {
              size 0.7 0.7 0.3
            }
          ]
        }
        physics Physics {
          density -1
          mass 6.246600
          centerOfMass [ -0.000688 -0.019458 0.034718 ]
          inertiaMatrix [
            4.614900e-02 5.884400e-02 1.022500e-01
            1.753200e-13 1.942200e-07 3.866300e-07
          ]
        }
      }
      DEF wheel1_steer_joint HingeJoint {
        jointParameters HingeJointParameters {
          axis 0.000000 0.000000 -1.000000
          anchor -0.185 0.185 0.011
        }
        device [
          RotationalMotor {
            name "wheel1_steer_joint"
            maxTorque 10000
          }
          PositionSensor {
            name "wheel1_steer_joint_sensor"
          }
        ]
        endPoint DEF wheel1_steer Solid {
          translation -0.185 0.185 0.011
          rotation 0.000000 0.000000 -1.000000 0.395745
          children [
            Shape {
              appearance DEF wheel1_steer_material PBRAppearance {
                roughness 1.000000
                metalness 0
              }
              geometry DEF wheel1_steer Mesh {
                url "../protos/robocon2022_r1_meshes/wheel_steer.STL"
              }
            }
            DEF wheel1_drive_joint HingeJoint {
              jointParameters HingeJointParameters {
                axis 0.385495 0.922710 0.000000
              }
              device [
                RotationalMotor {
                  name "wheel1_drive_joint"
                  maxTorque 10000
                }
                PositionSensor {
                  name "wheel1_drive_joint_sensor"
                }
              ]
              endPoint DEF wheel1_drive Solid {
                children [
                  Shape {
                    appearance DEF wheel1_drive_material PBRAppearance {
                      baseColor 0.101961 0.101961 0.101961
                      roughness 1.000000
                      metalness 0
                    }
                    geometry DEF wheel1_drive Mesh {
                      url "../protos/robocon2022_r1_meshes/wheel_drive.STL"
                    }
                  }
                ]
                name "wheel1_drive"
                boundingObject Transform {
                translation 3.07177e-10 -1.11991e-09 -4.60901e-15
                rotation 0.9665419415019838 -0.1813789890223998 -0.1813789890223998 1.60482
                children [
                  Cylinder {
                    height 0.06
                    radius 0.054
                  }
                ]
                }
                physics Physics {
                  density -1
                  mass 0.401054
                  centerOfMass [ -0.000314 0.004875 0.000037 ]
                  inertiaMatrix [
                    4.314577e-04 6.211847e-04 3.908145e-04
                    9.602743e-05 9.020996e-08 2.208855e-07
                  ]
                }
              }
            }
          ]
          name "wheel1_steer"
          boundingObject Cylinder {
          height 0.07
          radius 0.072
          }
          physics Physics {
            density -1
            mass 0.363584
            centerOfMass [ 0.000397 0.006577 0.006091 ]
            inertiaMatrix [
              4.836460e-04 5.902279e-04 8.726343e-04
              5.394418e-05 8.722056e-08 2.088125e-07
            ]
          }
        }
      }
      DEF wheel2_steer_joint HingeJoint {
        jointParameters HingeJointParameters {
          axis 0.000000 0.000000 -1.000000
          anchor 0.185000 0.179374 0.011000
        }
        device [
          RotationalMotor {
            name "wheel2_steer_joint"
            maxTorque 10000
          }
          PositionSensor {
            name "wheel2_steer_joint_sensor"
          }
        ]
        endPoint DEF wheel2_steer Solid {
          translation 0.185000 0.185000 0.011000
          rotation 0.000000 0.000000 1.000000 1.175052
          rotation 0 0 1 0.371
          children [
            Shape {
              appearance DEF wheel2_steer_material PBRAppearance {
                roughness 1.000000
                metalness 0
              }
              geometry DEF wheel2_steer Mesh {
                url "../protos/robocon2022_r1_meshes/wheel_steer.STL"
              }
            }
            DEF wheel2_drive_joint HingeJoint {
              jointParameters HingeJointParameters {
                axis -0.922710 -0.385495 0.000000
              }
              device [
                RotationalMotor {
                  name "wheel2_drive_joint"
                  maxTorque 10000
                }
                PositionSensor {
                  name "wheel2_drive_joint_sensor"
                }
              ]
              endPoint DEF wheel2_drive Solid {
                children [
                  Shape {
                    appearance DEF wheel2_drive_material PBRAppearance {
                      baseColor 0.101961 0.101961 0.101961
                      roughness 1.000000
                      metalness 0
                    }
                    geometry DEF wheel2_drive Mesh {
                      url "../protos/robocon2022_r1_meshes/wheel_drive.STL"
                    }
                  }
                ]
                name "wheel2_drive"
                boundingObject Transform {
                  translation 3.07177e-10 -1.11991e-09 -4.60901e-15
                  rotation 0.9665419415019838 -0.1813789890223998 -0.1813789890223998 1.60482
                  children [
                    Cylinder {
                      height 0.06
                      radius 0.054
                    }
                  ]
                }
                physics Physics {
                  density -1
                  mass 0.401054
                  centerOfMass [ 0.000751 0.005313 0.000037 ]
                  inertiaMatrix [
                    6.211847e-04 4.314577e-04 3.908145e-04
                    -9.602743e-05 -2.208855e-07 9.020996e-08
                  ]
                }
              }
            }
          ]
          name "wheel2_steer"
          boundingObject Cylinder {
          height 0.07
          radius 0.072
        }
          physics Physics {
            density -1
            mass 0.363584
            centerOfMass [ -0.000950 0.006023 0.006091 ]
            inertiaMatrix [
              5.902279e-04 4.836460e-04 8.726343e-04
              -5.394418e-05 -2.088125e-07 8.722056e-08
            ]
          }
        }
      }
      DEF wheel3_steer_joint HingeJoint {
        jointParameters HingeJointParameters {
          axis 0.000000 0.000000 -1.000000
          anchor 0.185000 -0.190626 0.011000
        }
        device [
          RotationalMotor {
            name "wheel3_steer_joint"
            maxTorque 10000
          }
          PositionSensor {
            name "wheel3_steer_joint_sensor"
          }
        ]
        endPoint DEF wheel3_steer Solid {
          translation 0.185000 -0.190626 0.011000
          rotation 0.000000 0.000000 1.000000 2.745848
          children [
            Shape {
              appearance DEF wheel3_steer_material PBRAppearance {
                roughness 1.000000
                metalness 0
              }
              geometry DEF wheel3_steer Mesh {
                url "../protos/robocon2022_r1_meshes/wheel_steer.STL"
              }
            }
            DEF wheel3_drive_joint HingeJoint {
              jointParameters HingeJointParameters {
                axis 0.385495 0.922710 0.000000
              }
              device [
                RotationalMotor {
                  name "wheel3_drive_joint"
                  maxTorque 10000
                }
                PositionSensor {
                  name "wheel3_drive_joint_sensor"
                }
              ]
              endPoint DEF wheel3_drive Solid {
                children [
                  Shape {
                    appearance DEF wheel3_drive_material PBRAppearance {
                      baseColor 0.898039 0.917647 0.929412
                      roughness 1.000000
                      metalness 0
                    }
                    geometry DEF wheel3_drive Mesh {
                      url "../protos/robocon2022_r1_meshes/wheel_drive.STL"
                    }
                  }
                ]
                name "wheel3_drive"
                boundingObject Transform {
                translation 3.07177e-10 -1.11991e-09 -4.60901e-15
                rotation 0.9665419415019838 -0.1813789890223998 -0.1813789890223998 1.60482
                children [
                  Cylinder {
                    height 0.06
                    radius 0.054
                  }
                ]
              }
                physics Physics {
                  density -1
                  mass 0.401054
                  centerOfMass [ 0.000314 0.000751 0.000037 ]
                  inertiaMatrix [
                    4.314577e-04 6.211847e-04 3.908145e-04
                    9.602743e-05 -9.020996e-08 -2.208855e-07
                  ]
                }
              }
            }
          ]
          name "wheel3_steer"
          boundingObject Cylinder {
          height 0.07
          radius 0.072
        }
          physics Physics {
            density -1
            mass 0.363584
            centerOfMass [ -0.000397 -0.000950 0.006091 ]
            inertiaMatrix [
              4.836460e-04 5.902279e-04 8.726343e-04
              5.394418e-05 -8.722056e-08 -2.088125e-07
            ]
          }
        }
      }
      DEF wheel4_steer_joint HingeJoint {
        jointParameters HingeJointParameters {
          axis 0.000000 0.000000 -1.000000
          anchor -0.185000 -0.190626 0.011000
        }
        device [
          RotationalMotor {
            name "wheel4_steer_joint"
            maxTorque 10000
          }
          PositionSensor {
            name "wheel4_steer_joint_sensor"
          }
        ]
        endPoint DEF wheel4_steer Solid {
          translation -0.185000 -0.190626 0.011000
          rotation 0.000000 0.000000 -1.000000 1.966541
          children [
            Shape {
              appearance DEF wheel4_steer_material PBRAppearance {
                roughness 1.000000
                metalness 0
              }
              geometry DEF wheel4_steer Mesh {
                url "../protos/robocon2022_r1_meshes/wheel_steer.STL"
              }
            }
            DEF wheel4_drive_joint HingeJoint {
              jointParameters HingeJointParameters {
                axis -0.922710 -0.385495 0.000000
              }
              device [
                RotationalMotor {
                  name "wheel4_drive_joint"
                  maxTorque 10000
                }
                PositionSensor {
                  name "wheel4_drive_joint_sensor"
                }
              ]
              endPoint DEF wheel4_drive Solid {
                children [
                  Shape {
                    appearance DEF wheel4_drive_material PBRAppearance {
                      baseColor 0.792157 0.819608 0.929412
                      roughness 1.000000
                      metalness 0
                    }
                    geometry DEF wheel4_drive Mesh {
                      url "../protos/robocon2022_r1_meshes/wheel_drive.STL"
                    }
                  }
                ]
                name "wheel4_drive"
                boundingObject Transform {
                translation 3.07177e-10 -1.11991e-09 -4.60901e-15
                rotation 0.9665419415019838 -0.1813789890223998 -0.1813789890223998 1.60482
                children [
                  Cylinder {
                    height 0.06
                    radius 0.054
                  }
                ]
              }
                physics Physics {
                  density -1
                  mass 0.401054
                  centerOfMass [ -0.000751 0.000314 0.000037 ]
                  inertiaMatrix [
                    6.211847e-04 4.314577e-04 3.908145e-04
                    -9.602743e-05 2.208855e-07 -9.020996e-08
                  ]
                }
              }
            }
          ]
          name "wheel4_steer"
          boundingObject Cylinder {
          height 0.07
          radius 0.072
        }
          physics Physics {
            density -1
            mass 0.363580
            centerOfMass [ 0.000950 -0.000397 0.006091 ]
            inertiaMatrix [
              5.902300e-04 4.836500e-04 8.726300e-04
              -5.394400e-05 2.088100e-07 -8.722100e-08
            ]
          }
        }
      }
      DEF gripper_base Solid {
        translation 0.000900 0.247000 0.238000
        children [
          Shape {
            appearance DEF gripper_base_material PBRAppearance {
              baseColor 0.898039 0.917647 0.929412
              roughness 1.000000
              metalness 0
            }
            geometry DEF gripper_base Mesh {
              url "../protos/robocon2022_r1_meshes/gripper_base.STL"
            }
          }
          DEF gripper_link1_joint HingeJoint {
            jointParameters HingeJointParameters {
              axis -1.000000 0.000000 0.000000
            }
            device [
              RotationalMotor {
                name "gripper_link1_joint"
                minPosition -3.33
                maxPosition 0.45
                maxTorque 10000
              }
              PositionSensor {
                name "gripper_link1_joint_sensor"
              }
            ]
            endPoint DEF gripper_link1 Solid {
              children [
                Shape {
                  appearance CorrodedMetal {
                  }
                  geometry DEF gripper_link1 Mesh {
                    url "../protos/robocon2022_r1_meshes/gripper_link1.STL"
                  }
                }
                DEF gripper_tip1_joint SliderJoint {
                  jointParameters JointParameters {
                    axis -1.000000 0.000000 0.000000
                  }
                  device [
                    LinearMotor {
                      name "gripper_tip1_joint"
                      maxPosition 0.05
                      maxForce 10000
                    }
                    PositionSensor {
                      name "gripper_tip1_joint_sensor"
                    }
                  ]
                  endPoint DEF gripper_tip1 Solid {
                    translation 0.000000 0.116700 -0.062317
                    children [
                      Shape {
                        appearance DEF gripper_tip1_material PBRAppearance {
                          baseColor 0.666670 0.698040 0.768630
                          roughness 1.000000
                          metalness 0
                        }
                        geometry DEF gripper_tip1 Mesh {
                          url "../protos/robocon2022_r1_meshes/gripper_tip1.STL"
                        }
                      }
                    ]
                    name "gripper_tip1"
                    boundingObject USE gripper_tip1
                    physics Physics {
                      density -1
                      mass 0.081252
                      centerOfMass [ -0.066535 0.051401 -0.021920 ]
                      inertiaMatrix [
                        4.678600e-05 3.127100e-05 5.787800e-05
                        1.336900e-06 3.105700e-07 -2.496300e-06
                      ]
                    }
                  }
                }
                DEF gripper_tip2_joint SliderJoint {
                  jointParameters JointParameters {
                  }
                  device [
                    LinearMotor {
                      name "gripper_tip2_joint"
                      maxPosition 0.05
                      maxForce 10000
                    }
                    PositionSensor {
                      name "gripper_tip2_joint_sensor"
                    }
                  ]
                  endPoint DEF gripper_tip2 Solid {
                    translation 0.000000 0.116700 -0.062317
                    children [
                      Shape {
                        appearance DEF gripper_tip2_material PBRAppearance {
                          baseColor 0.600000 0.600000 0.600000
                          roughness 1.000000
                          metalness 0
                        }
                        geometry DEF gripper_tip2 Mesh {
                          url "../protos/robocon2022_r1_meshes/gripper_tip2.STL"
                        }
                      }
                    ]
                    name "gripper_tip2"
                    boundingObject USE gripper_tip2
                    physics Physics {
                      density -1
                      mass 0.081252
                      centerOfMass [ 0.066535 0.051391 -0.021837 ]
                      inertiaMatrix [
                        4.678600e-05 3.150600e-05 5.764300e-05
                        -1.372500e-06 5.062400e-09 -3.527700e-06
                      ]
                    }
                  }
                }
              ]
              name "gripper_link1"
              boundingObject Box {
              size 0.01 0.01 0.01
              }
              physics Physics {
                density -1
                mass 0.263407
                centerOfMass [ -0.000000 0.117387 -0.076848 ]
                inertiaMatrix [
                  1.326783e-04 2.943424e-04 2.548575e-04
                  -3.883752e-19 1.349691e-19 4.425126e-06
                ]
              }
            }
          }
        ]
        name "gripper_base"
        boundingObject Box {
        size 0.01 0.01 0.01
        }
        physics Physics {
          density -1
          mass 0.608015
          centerOfMass [ -0.016272 0.004383 -0.083365 ]
          inertiaMatrix [
            7.587752e-04 1.216608e-03 6.518012e-04
            -4.298840e-09 4.673784e-09 1.231857e-06
          ]
        }
      }
    ]
    name IS name
    boundingObject USE base_link
    physics Physics {
      density -1
      mass 0.013217
      centerOfMass [ 0.351000 0.245000 0.010000 ]
      inertiaMatrix [
        1.501977e-06 1.501977e-06 2.739313e-06
        -5.940696e-37 -1.941117e-23 1.836710e-37
      ]
    }
  }
}
